Workbook
Name all_brassica: 'PROXY def''ns'!$I$4:$I$20
Name all_fish: 'PROXY def''ns'!$F$98:$F$104
Name almond: 'PROXY def''ns'!$F$73:$F$74
Name apple: 'PROXY def''ns'!$F$55:$F$56
Name apricot: 'PROXY def''ns'!$F$61:$F$62
Name artichoke_globe: 'PROXY def''ns'!$F$90:$F$91
Name asparagus: 'PROXY def''ns'!$F$86:$F$87
Name banana: 'PROXY def''ns'!$F$92:$F$93
Name bean_dry: 'PROXY def''ns'!$F$26:$F$27
Name bean_snap_succulent: 'PROXY def''ns'!$F$22:$F$23
Name beer: 'PROXY def''ns'!$F$125:$F$126
Name berry: 'PROXY def''ns'!$B$4:$B$13
Name brass_grns_E: 'Pivot Table_CED'!$T$11
Name brass_grns_GHG: 'Pivot Table_CED'!$U$11
Name brassica: 'PROXY def''ns'!$B$22:$B$27
Name brassica_greens: 'PROXY def''ns'!$B$28:$B$35
Name brassica_roots: 'PROXY def''ns'!$B$36:$B$40
Name broccoli: 'PROXY def''ns'!$F$17:$F$18
Name carrot: 'PROXY def''ns'!$F$4:$F$5
Name cassava: 'PROXY def''ns'!$F$6:$F$7
Name celery: 'PROXY def''ns'!$F$88:$F$89
Name cherry: 'PROXY def''ns'!$F$59:$F$60
Name Chicken: 'PROXY def''ns'!$F$118:$F$119
Name choc_coffee_tea: 'PROXY def''ns'!$I$110:$I$117
Name citrus: 'PROXY def''ns'!$B$41:$B$52
Name clover_seed: 'PROXY def''ns'!$B$15:$B$16
Name coconut_meat: 'PROXY def''ns'!$F$75:$F$76
Name coconut_oil: 'PROXY def''ns'!$I$65:$I$66
Name corn_flour: 'PROXY def''ns'!$F$121:$F$122
Name corn_starch: 'PROXY def''ns'!$F$123:$F$124
Name cucumber: 'PROXY def''ns'!$F$45:$F$46
Name cucurbits: 'PROXY def''ns'!$I$122:$I$132
Name dried_herbs: 'PROXY def''ns'!$B$53:$B$55
Name endive: 'PROXY def''ns'!$F$13:$F$14
Name Escarole: 'PROXY def''ns'!$F$111:$F$112
Name flours: 'PROXY def''ns'!$I$68:$I$73
Name Fluid_milk_cow: 'PROXY def''ns'!$I$119:$I$120
Name Food_Form: '[1]List Names'!$C$3:$C$8
Name Food_Type: '[1]List Names'!$B$3:$B$16
Name FoodForm: #REF!
Name FoodTypes: #REF!
Name fresh_herbs: 'PROXY def''ns'!$B$56:$B$65
Name ginger: 'PROXY def''ns'!$F$11:$F$12
Name grains: 'PROXY def''ns'!$B$66:$B$77
Name grape: 'PROXY def''ns'!$F$69:$F$70
Name grape_raisin: 'PROXY def''ns'!$F$67:$F$68
Name greens: 'PROXY def''ns'!$B$78:$B$88
Name honey: 'PROXY def''ns'!$F$109:$F$110
Name legume_seed: 'PROXY def''ns'!$I$23:$I$32
Name lentil_seed: 'PROXY def''ns'!$F$28:$F$29
Name Maple_syrup: 'PROXY def''ns'!$F$115:$F$116
Name melon: 'PROXY def''ns'!$F$40:$F$43
Name nightshades: 'PROXY def''ns'!$F$34:$F$37
Name nonruminant_meat: 'PROXY def''ns'!$F$139:$F$144
Name nut: 'PROXY def''ns'!$B$89:$B$101
Name oat_flour: 'PROXY def''ns'!$F$127:$F$128
Name oils: 'PROXY def''ns'!$B$148:$B$161
Name oilseed_oil: 'PROXY def''ns'!$B$140:$B$146
Name onion_bulb: 'PROXY def''ns'!$F$15:$F$16
Name orange: 'PROXY def''ns'!$F$53:$F$54

Sheet DESCRIPTION
A2: Welcome to dataFIELD version 1.0 - (database of Food Impacts on the Environment for Linking to Diets)
B3: This version links greenhouse gas emissions (GHGE) and cumulative energy demand (CED) associated with PRODUCTION of food commodities to the 2005-2010 FCID commodity codes. | S3: http://fcid.foodrisk.org/
B4: FCID commodity codes can then be used to link to NHANES datasets.
A5: The methods used to compile this database are described in the journal article:
B6: Heller MC, Willits-Smith A, Meyer R, Keoleian GA, Rose D (2018) Greenhouse gas emissions and energy use associated with production of individual self-selected U.S. diets. Environ Res Lett 13
B7: https://doi.org/10.1088/1748-9326/aab0ac
A8: *MODIFICATIONS TO THIS WORKBOOK ARE AT YOUR OWN RISK. The modifier is responsible for assuring that functionality is maintained. No efforts have been made to "lock" or otherwise protect necessary functionality.
A10: Workbook Contents
A11: below are brief descriptions of the sheets in this workbook. For more complete descriptions and suggestions for use, see the accompanying document:
B13: FCID Linkages | C13: contains final (utlized) impact factors. Assigns impact factors to FCID commodities, assigns proxies, and executes necessary mass conversions
B14: literature entries | C14: raw data entries logged in literature review, including metadata, references
B15: Pivot Table_GHG | C15: GHGE data from "literature entries" sheet aggregated by specific food type and boundary condition (farm gate vs. processor gate)
B16: Pivot Table_CED | C16: CED data from "literature entries" sheet aggregated by specific food type and boundary condition (farm gate vs. processor gate)
B17: PROXY def'ns | C17: contains proxy definitions used to fill FICD commodities without direct matches.
B18: MassConv | C18: compilation of mass conversions used to account for inedible portions, etc. The source of the conversion factor used for each FCID entry is defined in column "I" of the FCID Linkages sheet

Sheet FCID linkages
F1: UTILIZED IMPACT FACTORS | J1: farm gate (=1) | K1: PROXY DEFINITION | L1: ENERGY USE MJ/kg | P1: GHG Emissions (kg CO2eq/kg) | T1: additional processing inputs for select foods | W1: VARIANCE CALCULATIONS
E2: number of times specific commodity appears in FCID recipe files | F2: CED | G2: GHG | L2: PROXY? | P2: PROXY? | T2: Energy (MJ) | U2: GHG (kgCO2eq) | W2: Energy Use (MJ/kg) | AB2: GHGE
A3: FCID_Code | B3: FCID_Desc | C3: Weight_Basis_ as defined by FCID | D3: Comments (from FCID) | E3: N_Cases | F3: MJ / kg | G3: CO2 eq / kg | H3: weight Conversion Factor | I3: conversion factor source | J3: or processor gate (=2)? | M3: # of datapoints | N3: N-average | O3: Std. Dev | Q3: # of datapoints | R3: N-average | S3: Std. Dev | W3: basis | X3: n | Y3: proxy group mean | Z3: SD (group or indiv food) | AA3: scaled SD (group SD*food mean/group mean) | AB3: basis | AC3: n | AD3: proxy group mean | AE3: SD (group or indiv food) | AF3: scaled SD (group SD*food mean/group mean)
A4: 101050000 | B4: Beet, garden, roots | C4: weight of roots; juice | E4: 659 | F4: =N4*H4+T4 -> 1.221 | G4: =R4*H4+U4 -> 0.19425 | H4: 1.11 | I4: AgHB | J4: 1 | L4: =IF(ISERROR(GETPIVOTDATA(IF($J4=1,"Count of ACTIVE CED, FARM GATE (MJ/kg)","Count of CED, processor gate (MJ/kg)"),'Pivot Table_CED'!$A$3,"SUB TYPE",$B4)),"PROXY",IF(GETPIVOTDATA(IF($J4=1,"Count of ACTIVE CED, FARM GATE (MJ/kg)","Count of CED, processor gate (MJ/kg)"),'Pivot Table_CED'!$A$3,"SUB TYPE",$B4)=0,"PROXY","DB value")) -> DB value | M4: =IF($L4="PROXY",DCOUNT('literature entries'!$D:$AI,IF($J4=1,"ACTIVE CED, FARM GATE (MJ/kg)","CED, processor gate (MJ/kg)"),INDIRECT($K4)),GETPIVOTDATA(IF($J4=1,"Count of ACTIVE CED, FARM GATE (MJ/kg)","Count of CED, processor gate (MJ/kg)"),'Pivot Table_CED'!$A$3,"SUB TYPE",$B4)) -> 1 | N4: =IF($L4="PROXY",DAVERAGE('literature entries'!$D:$AI,IF($J4=1,"ACTIVE CED, FARM GATE (MJ/kg)","CED, processor gate (MJ/kg)"),INDIRECT($K4)),GETPIVOTDATA(IF($J4=1,"Average of ACTIVE CED, FARM GATE (MJ/kg)","Average of CED, processor gate (MJ/kg)"),'Pivot Table_CED'!$A$3,"SUB TYPE",$B4)) -> 1.1 | O4: =IF($L4="PROXY",DSTDEV('literature entries'!D:AF,IF($J4=1,"ACTIVE CED, FARM GATE (MJ/kg)","CED, processor gate (MJ/kg)"),INDIRECT($K4)),GETPIVOTDATA(IF($J4=1,"StdDev of ACTIVE CED, FARM GATE (MJ/kg)","StdDev of CED, processor gate (MJ/kg)"),'Pivot Table_CED'!$A$3,"SUB TYPE",$B4)) -> 0 | P4: =IF(ISERROR(GETPIVOTDATA(IF($J4=1,"Count of ACTIVE GHGE, FARM GATE (kg CO2e/kg)","Count of GHGE, processor gate (kg CO2e/kg)"),'Pivot Table_GHG'!$A$3,"SUB TYPE",$B4)),"PROXY",IF(GETPIVOTDATA(IF($J4=1,"Count of ACTIVE GHGE, FARM GATE (kg CO2e/kg)","Count of GHGE, processor gate (kg CO2e/kg)"),'Pivot Table_GHG'!$A$3,"SUB TYPE",$B4)=0,"PROXY","DB value")) -> DB value | Q4: =IF($P4="PROXY",DCOUNT('literature entries'!$D:$AI,IF($J4=1,"ACTIVE GHGE, FARM GATE (kg CO2e/kg)","GHGE, processor gate (kg CO2e/kg)"),INDIRECT($K4)),GETPIVOTDATA(IF($J4=1,"ACTIVE GHGE, FARM GATE (kg CO2e/kg)","Count of GHGE, processor gate (kg CO2e/kg)"),'Pivot Table_GHG'!$A$3,"SUB TYPE",$B4)) -> 2 | R4: =IF($P4="PROXY",DAVERAGE('literature entries'!$D:$AI,IF($J4=1,"ACTIVE GHGE, FARM GATE (kg CO2e/kg)","GHGE, processor gate (kg CO2e/kg)"),INDIRECT($K4)),GETPIVOTDATA(IF($J4=1,"Average of ACTIVE GHGE, FARM GATE (kg CO2e/kg)","Average of GHGE, processor gate (kg CO2e/kg)"),'Pivot Table_GHG'!$A$3,"SUB TYPE",$B4)) -> 0.175 | S4: =IF($P4="PROXY",DSTDEV('literature entries'!$D:$AI,IF($J4=1,"ACTIVE GHGE, FARM GATE (kg CO2e/kg)","GHGE, processor gate (kg CO2e/kg)"),INDIRECT($K4)),GETPIVOTDATA(IF($J4=1,"StdDev of ACTIVE GHGE, FARM GATE (kg CO2e/kg)","StdDev of GHGE, processor gate (kg CO2e/kg)"),'Pivot Table_GHG'!$A$3,"SUB TYPE",$B4)) -> 0.091923882 | W4: roots | X4: =IF($W4="DIRECT",M4,DCOUNT('literature entries'!$D:$AI,IF($J4=1,"ACTIVE CED, FARM GATE (MJ/kg)","CED, processor gate (MJ/kg)"),INDIRECT($W4))) -> 14 | Y4: =IF($W4="DIRECT","",DAVERAGE('literature entries'!$D:$AI,IF($J4=1,"ACTIVE CED, FARM GATE (MJ/kg)","CED, processor gate (MJ/kg)"),INDIRECT($W4))) -> 1.4220714 | Z4: =IF($W4="DIRECT",$O4,DSTDEV('literature entries'!$D:$AI,IF($J4=1,"ACTIVE CED, FARM GATE (MJ/kg)","CED, processor gate (MJ/kg)"),INDIRECT($W4))) -> 0.57442044 | AA4: =IF($W4="DIRECT",$O4,$Z4/$Y4*$N4) -> 0.44432542 | AB4: roots | AC4: =IF($AB4="DIRECT",Q4,DCOUNT('literature entries'!$D:$AI,IF($J4=1,"ACTIVE GHGE, FARM GATE (kg CO2e/kg)","GHGE, processor gate (kg CO2e/kg)"),INDIRECT($AB4))) -> 25 | AD4: =IF($AB4="DIRECT","",DAVERAGE('literature entries'!$D:$AI,IF($J4=1,"ACTIVE GHGE, FARM GATE (kg CO2e/kg)","GHGE, processor gate (kg CO2e/kg)"),INDIRECT($AB4))) -> 0.2134 | AE4: =IF($AB4="DIRECT",$S4,DSTDEV('literature entries'!$D:$AI,IF($J4=1,"ACTIVE GHGE, FARM GATE (kg CO2e/kg)","GHGE, processor gate (kg CO2e/kg)"),INDIRECT($AB4))) -> 0.17992035 | AF4: =IF($AB4="DIRECT",$S4,$AE4/$AD4*$R4) -> 0.14754481
A5: 101052000 | B5: Beet, sugar | C5: dry weight of sugar (sucrose) | D5: Sucrose is a disaccharide obtained from sugar cane and sugar beet. | E5: 49979 | F5: =N5*H5+T5 -> 4.5742357 | G5: =R5*H5+U5 -> 0.39078306 | H5: 1 | I5: FICRCD | J5: 2 | L5: =IF(ISERROR(GETPIVOTDATA(IF($J5=1,"Count of ACTIVE CED, FARM GATE (MJ/kg)","Count of CED, processor gate (MJ/kg)"),'Pivot Table_CED'!$A$3,"SUB TYPE",$B5)),"PROXY",IF(GETPIVOTDATA(IF($J5=1,"Count of ACTIVE CED, FARM GATE (MJ/kg)","Count of CED, processor gate (MJ/kg)"),'Pivot Table_CED'!$A$3,"SUB TYPE",$B5)=0,"PROXY","DB value")) -> DB value | M5: =IF($L5="PROXY",DCOUNT('literature entries'!$D:$AI,IF($J5=1,"ACTIVE CED, FARM GATE (MJ/kg)","CED, processor gate (MJ/kg)"),INDIRECT($K5)),GETPIVOTDATA(IF($J5=1,"Count of ACTIVE CED, FARM GATE (MJ/kg)","Count of CED, processor gate (MJ/kg)"),'Pivot Table_CED'!$A$3,"SUB TYPE",$B5)) -> 4 | N5: =IF($L5="PROXY",DAVERAGE('literature entries'!$D:$AI,IF($J5=1,"ACTIVE CED, FARM GATE (MJ/kg)","CED, processor gate (MJ/kg)"),INDIRECT($K5)),GETPIVOTDATA(IF($J5=1,"Average of ACTIVE CED, FARM GATE (MJ/kg)","Average of CED, processor gate (MJ/kg)"),'Pivot Table_CED'!$A$3,"SUB TYPE",$B5)) -> 4.5742357 | O5: =IF($L5="PROXY",DSTDEV('literature entries'!D:AI,IF($J5=1,"ACTIVE CED, FARM GATE (MJ/kg)","CED, processor gate (MJ/kg)"),INDIRECT($K5)),GETPIVOTDATA(IF($J5=1,"StdDev of ACTIVE CED, FARM GATE (MJ/kg)","StdDev of CED, processor gate (MJ/kg)"),'Pivot Table_CED'!$A$3,"SUB TYPE",$B5)) -> 0.63688081 | P5: =IF(ISERROR(GETPIVOTDATA(IF($J5=1,"Count of ACTIVE GHGE, FARM GATE (kg CO2e/kg)","Count of GHGE, processor gate (kg CO2e/kg)"),'Pivot Table_GHG'!$A$3,"SUB TYPE",$B5)),"PROXY",IF(GETPIVOTDATA(IF($J5=1,"Count of ACTIVE GHGE, FARM GATE (kg CO2e/kg)","Count of GHGE, processor gate (kg CO2e/kg)"),'Pivot Table_GHG'!$A$3,"SUB TYPE",$B5)=0,"PROXY","DB value")) -> DB value | Q5: =IF($P5="PROXY",DCOUNT('literature entries'!$D:$AI,IF($J5=1,"ACTIVE GHGE, FARM GATE (kg CO2e/kg)","GHGE, processor gate (kg CO2e/kg)"),INDIRECT($K5)),GETPIVOTDATA(IF($J5=1,"ACTIVE GHGE, FARM GATE (kg CO2e/kg)","Count of GHGE, processor gate (kg CO2e/kg)"),'Pivot Table_GHG'!$A$3,"SUB TYPE",$B5)) -> 4 | R5: =IF($P5="PROXY",DAVERAGE('literature entries'!$D:$AI,IF($J5=1,"ACTIVE GHGE, FARM GATE (kg CO2e/kg)","GHGE, processor gate (kg CO2e/kg)"),INDIRECT($K5)),GETPIVOTDATA(IF($J5=1,"Average of ACTIVE GHGE, FARM GATE (kg CO2e/kg)","Average of GHGE, processor gate (kg CO2e/kg)"),'Pivot Table_GHG'!$A$3,"SUB TYPE",$B5)) -> 0.39078306 | S5: =IF($P5="PROXY",DSTDEV('literature entries'!$D:$AI,IF($J5=1,"ACTIVE GHGE, FARM GATE (kg CO2e/kg)","GHGE, processor gate (kg CO2e/kg)"),INDIRECT($K5)),GETPIVOTDATA(IF($J5=1,"StdDev of ACTIVE GHGE, FARM GATE (kg CO2e/kg)","StdDev of GHGE, processor gate (kg CO2e/kg)"),'Pivot Table_GHG'!$A$3,"SUB TYPE",$B5)) -> 0.076284475 | W5: sweeteners | X5: =IF($W5="DIRECT",M5,DCOUNT('literature entries'!$D:$AI,IF($J5=1,"ACTIVE CED, FARM GATE (MJ/kg)","CED, processor gate (MJ/kg)"),INDIRECT($W5))) -> 14 | Y5: =IF($W5="DIRECT","",DAVERAGE('literature entries'!$D:$AI,IF($J5=1,"ACTIVE CED, FARM GATE (MJ/kg)","CED, processor gate (MJ/kg)"),INDIRECT($W5))) -> 8.8453456 | Z5: =IF($W5="DIRECT",$O5,DSTDEV('literature entries'!$D:$AI,IF($J5=1,"ACTIVE CED, FARM GATE (MJ/kg)","CED, processor gate (MJ/kg)"),INDIRECT($W5))) -> 17.468328 | AA5: =IF($W5="DIRECT",$O5,$Z5/$Y5*$N5) -> 9.0334799 | AB5: sweeteners | AC5: =IF($AB5="DIRECT",Q5,DCOUNT('literature entries'!$D:$AI,IF($J5=1,"ACTIVE GHGE, FARM GATE (kg CO2e/kg)","GHGE, processor gate (kg CO2e/kg)"),INDIRECT($AB5))) -> 13 | AD5: =IF($AB5="DIRECT","",DAVERAGE('literature entries'!$D:$AI,IF($J5=1,"ACTIVE GHGE, FARM GATE (kg CO2e/kg)","GHGE, processor gate (kg CO2e/kg)"),INDIRECT($AB5))) -> 1.0611859 | AE5: =IF($AB5="DIRECT",$S5,DSTDEV('literature entries'!$D:$AI,IF($J5=1,"ACTIVE GHGE, FARM GATE (kg CO2e/kg)","GHGE, processor gate (kg CO2e/kg)"),INDIRECT($AB5))) -> 1.8055997 | AF5: =IF($AB5="DIRECT",$S5,$AE5/$AD5*$R5) -> 0.66491438
A6: 101053000 | B6: Beet, sugar, molasses | C6: weight of molasses | E6: 7656 | F6: =N6*H6+T6 -> 3.47585 | G6: =R6*H6+U6 -> 0.2875925 | H6: 1 | I6: FICRCD | J6: 2 | L6: =IF(ISERROR(GETPIVOTDATA(IF($J6=1,"Count of ACTIVE CED, FARM GATE (MJ/kg)","Count of CED, processor gate (MJ/kg)"),'Pivot Table_CED'!$A$3,"SUB TYPE",$B6)),"PROXY",IF(GETPIVOTDATA(IF($J6=1,"Count of ACTIVE CED, FARM GATE (MJ/kg)","Count of CED, processor gate (MJ/kg)"),'Pivot Table_CED'!$A$3,"SUB TYPE",$B6)=0,"PROXY","DB value")) -> DB value | M6: =IF($L6="PROXY",DCOUNT('literature entries'!$D:$AI,IF($J6=1,"ACTIVE CED, FARM GATE (MJ/kg)","CED, processor gate (MJ/kg)"),INDIRECT($K6)),GETPIVOTDATA(IF($J6=1,"Count of ACTIVE CED, FARM GATE (MJ/kg)","Count of CED, processor gate (MJ/kg)"),'Pivot Table_CED'!$A$3,"SUB TYPE",$B6)) -> 4 | N6: =IF($L6="PROXY",DAVERAGE('literature entries'!$D:$AI,IF($J6=1,"ACTIVE CED, FARM GATE (MJ/kg)","CED, processor gate (MJ/kg)"),INDIRECT($K6)),GETPIVOTDATA(IF($J6=1,"Average of ACTIVE CED, FARM GATE (MJ/kg)","Average of CED, processor gate (MJ/kg)"),'Pivot Table_CED'!$A$3,"SUB TYPE",$B6)) -> 3.47585 | O6: =IF($L6="PROXY",DSTDEV('literature entries'!D:AI,IF($J6=1,"ACTIVE CED, FARM GATE (MJ/kg)","CED, processor gate (MJ/kg)"),INDIRECT($K6)),GETPIVOTDATA(IF($J6=1,"StdDev of ACTIVE CED, FARM GATE (MJ/kg)","StdDev of CED, processor gate (MJ/kg)"),'Pivot Table_CED'!$A$3,"SUB TYPE",$B6)) -> 0.3775474 | P6: =IF(ISERROR(GETPIVOTDATA(IF($J6=1,"Count of ACTIVE GHGE, FARM GATE (kg CO2e/kg)","Count of GHGE, processor gate (kg CO2e/kg)"),'Pivot Table_GHG'!$A$3,"SUB TYPE",$B6)),"PROXY",IF(GETPIVOTDATA(IF($J6=1,"Count of ACTIVE GHGE, FARM GATE (kg CO2e/kg)","Count of GHGE, processor gate (kg CO2e/kg)"),'Pivot Table_GHG'!$A$3,"SUB TYPE",$B6)=0,"PROXY","DB value")) -> DB value | Q6: =IF($P6="PROXY",DCOUNT('literature entries'!$D:$AI,IF($J6=1,"ACTIVE GHGE, FARM GATE (kg CO2e/kg)","GHGE, processor gate (kg CO2e/kg)"),INDIRECT($K6)),GETPIVOTDATA(IF($J6=1,"ACTIVE GHGE, FARM GATE (kg CO2e/kg)","Count of GHGE, processor gate (kg CO2e/kg)"),'Pivot Table_GHG'!$A$3,"SUB TYPE",$B6)) -> 4 | R6: =IF($P6="PROXY",DAVERAGE('literature entries'!$D:$AI,IF($J6=1,"ACTIVE GHGE, FARM GATE (kg CO2e/kg)","GHGE, processor gate (kg CO2e/kg)"),INDIRECT($K6)),GETPIVOTDATA(IF($J6=1,"Average of ACTIVE GHGE, FARM GATE (kg CO2e/kg)","Average of GHGE, processor gate (kg CO2e/kg)"),'Pivot Table_GHG'!$A$3,"SUB TYPE",$B6)) -> 0.2875925 | S6: =IF($P6="PROXY",DSTDEV('literature entries'!$D:$AI,IF($J6=1,"ACTIVE GHGE, FARM GATE (kg CO2e/kg)","GHGE, processor gate (kg CO2e/kg)"),INDIRECT($K6)),GETPIVOTDATA(IF($J6=1,"StdDev of ACTIVE GHGE, FARM GATE (kg CO2e/kg)","StdDev of GHGE, processor gate (kg CO2e/kg)"),'Pivot Table_GHG'!$A$3,"SUB TYPE",$B6)) -> 0.047032512 | W6: sweeteners | X6: =IF($W6="DIRECT",M6,DCOUNT('literature entries'!$D:$AI,IF($J6=1,"ACTIVE CED, FARM GATE (MJ/kg)","CED, processor gate (MJ/kg)"),INDIRECT($W6))) -> 14 | Y6: =IF($W6="DIRECT","",DAVERAGE('literature entries'!$D:$AI,IF($J6=1,"ACTIVE CED, FARM GATE (MJ/kg)","CED, processor gate (MJ/kg)"),INDIRECT($W6))) -> 8.8453456 | Z6: =IF($W6="DIRECT",$O6,DSTDEV('literature entries'!$D:$AI,IF($J6=1,"ACTIVE CED, FARM GATE (MJ/kg)","CED, processor gate (MJ/kg)"),INDIRECT($W6))) -> 17.468328 | AA6: =IF($W6="DIRECT",$O6,$Z6/$Y6*$N6) -> 6.8643208 | AB6: sweeteners | AC6: =IF($AB6="DIRECT",Q6,DCOUNT('literature entries'!$D:$AI,IF($J6=1,"ACTIVE GHGE, FARM GATE (kg CO2e/kg)","GHGE, processor gate (kg CO2e/kg)"),INDIRECT($AB6))) -> 13 | AD6: =IF($AB6="DIRECT","",DAVERAGE('literature entries'!$D:$AI,IF($J6=1,"ACTIVE GHGE, FARM GATE (kg CO2e/kg)","GHGE, processor gate (kg CO2e/kg)"),INDIRECT($AB6))) -> 1.0611859 | AE6: =IF($AB6="DIRECT",$S6,DSTDEV('literature entries'!$D:$AI,IF($J6=1,"ACTIVE GHGE, FARM GATE (kg CO2e/kg)","GHGE, processor gate (kg CO2e/kg)"),INDIRECT($AB6))) -> 1.8055997 | AF6: =IF($AB6="DIRECT",$S6,$AE6/$AD6*$R6) -> 0.48933644
A7: 101067000 | B7: Burdock | C7: weight of roots | E7: 2 | F7: =N7*H7+T7 -> 1.891355 | G7: =R7*H7+U7 -> 0.283822 | H7: 1.33 | I7: NNDSR28 | J7: 1 | K7: roots | L7: =IF(ISERROR(GETPIVOTDATA(IF($J7=1,"Count of ACTIVE CED, FARM GATE (MJ/kg)","Count of CED, processor gate (MJ/kg)"),'Pivot Table_CED'!$A$3,"SUB TYPE",$B7)),"PROXY",IF(GETPIVOTDATA(IF($J7=1,"Count of ACTIVE CED, FARM GATE (MJ/kg)","Count of CED, processor gate (MJ/kg)"),'Pivot Table_CED'!$A$3,"SUB TYPE",$B7)=0,"PROXY","DB value")) -> PROXY | M7: =IF($L7="PROXY",DCOUNT('literature entries'!$D:$AI,IF($J7=1,"ACTIVE CED, FARM GATE (MJ/kg)","CED, processor gate (MJ/kg)"),INDIRECT($K7)),GETPIVOTDATA(IF($J7=1,"Count of ACTIVE CED, FARM GATE (MJ/kg)","Count of CED, processor gate (MJ/kg)"),'Pivot Table_CED'!$A$3,"SUB TYPE",$B7)) -> 14 | N7: =IF($L7="PROXY",DAVERAGE('literature entries'!$D:$AI,IF($J7=1,"ACTIVE CED, FARM GATE (MJ/kg)","CED, processor gate (MJ/kg)"),INDIRECT($K7)),GETPIVOTDATA(IF($J7=1,"Average of ACTIVE CED, FARM GATE (MJ/kg)","Average of CED, processor gate (MJ/kg)"),'Pivot Table_CED'!$A$3,"SUB TYPE",$B7)) -> 1.4220714 | O7: =IF($L7="PROXY",DSTDEV('literature entries'!D:AI,IF($J7=1,"ACTIVE CED, FARM GATE (MJ/kg)","CED, processor gate (MJ/kg)"),INDIRECT($K7)),GETPIVOTDATA(IF($J7=1,"StdDev of ACTIVE CED, FARM GATE (MJ/kg)","StdDev of CED, processor gate (MJ/kg)"),'Pivot Table_CED'!$A$3,"SUB TYPE",$B7)) -> 0.57442044 | P7: =IF(ISERROR(GETPIVOTDATA(IF($J7=1,"Count of ACTIVE GHGE, FARM GATE (kg CO2e/kg)","Count of GHGE, processor gate (kg CO2e/kg)"),'Pivot Table_GHG'!$A$3,"SUB TYPE",$B7)),"PROXY",IF(GETPIVOTDATA(IF($J7=1,"Count of ACTIVE GHGE, FARM GATE (kg CO2e/kg)","Count of GHGE, processor gate (kg CO2e/kg)"),'Pivot Table_GHG'!$A$3,"SUB TYPE",$B7)=0,"PROXY","DB value")) -> PROXY | Q7: =IF($P7="PROXY",DCOUNT('literature entries'!$D:$AI,IF($J7=1,"ACTIVE GHGE, FARM GATE (kg CO2e/kg)","GHGE, processor gate (kg CO2e/kg)"),INDIRECT($K7)),GETPIVOTDATA(IF($J7=1,"ACTIVE GHGE, FARM GATE (kg CO2e/kg)","Count of GHGE, processor gate (kg CO2e/kg)"),'Pivot Table_GHG'!$A$3,"SUB TYPE",$B7)) -> 25 | R7: =IF($P7="PROXY",DAVERAGE('literature entries'!$D:$AI,IF($J7=1,"ACTIVE GHGE, FARM GATE (kg CO2e/kg)","GHGE, processor gate (kg CO2e/kg)"),INDIRECT($K7)),GETPIVOTDATA(IF($J7=1,"Average of ACTIVE GHGE, FARM GATE (kg CO2e/kg)","Average of GHGE, processor gate (kg CO2e/kg)"),'Pivot Table_GHG'!$A$3,"SUB TYPE",$B7)) -> 0.2134 | S7: =IF($P7="PROXY",DSTDEV('literature entries'!$D:$AI,IF($J7=1,"ACTIVE GHGE, FARM GATE (kg CO2e/kg)","GHGE, processor gate (kg CO2e/kg)"),INDIRECT($K7)),GETPIVOTDATA(IF($J7=1,"StdDev of ACTIVE GHGE, FARM GATE (kg CO2e/kg)","StdDev of GHGE, processor gate (kg CO2e/kg)"),'Pivot Table_GHG'!$A$3,"SUB TYPE",$B7)) -> 0.17992035 | W7: =IF(L7="PROXY",IF(M7>=5,K7,"need group"),IF(M7>=5,"DIRECT","need group")) -> roots | X7: =IF($W7="DIRECT",M7,DCOUNT('literature entries'!$D:$AI,IF($J7=1,"ACTIVE CED, FARM GATE (MJ/kg)","CED, processor gate (MJ/kg)"),INDIRECT($W7))) -> 14 | Y7: =IF($W7="DIRECT","",DAVERAGE('literature entries'!$D:$AI,IF($J7=1,"ACTIVE CED, FARM GATE (MJ/kg)","CED, processor gate (MJ/kg)"),INDIRECT($W7))) -> 1.4220714 | Z7: =IF($W7="DIRECT",$O7,DSTDEV('literature entries'!$D:$AI,IF($J7=1,"ACTIVE CED, FARM GATE (MJ/kg)","CED, processor gate (MJ/kg)"),INDIRECT($W7))) -> 0.57442044 | AA7: =IF($W7="DIRECT",$O7,$Z7/$Y7*$N7) -> 0.57442044 | AB7: =IF(P7="PROXY",IF(Q7>=5,K7,"need group"),IF(Q7>=5,"DIRECT","need group")) -> roots | AC7: =IF($AB7="DIRECT",Q7,DCOUNT('literature entries'!$D:$AI,IF($J7=1,"ACTIVE GHGE, FARM GATE (kg CO2e/kg)","GHGE, processor gate (kg CO2e/kg)"),INDIRECT($AB7))) -> 25 | AD7: =IF($AB7="DIRECT","",DAVERAGE('literature entries'!$D:$AI,IF($J7=1,"ACTIVE GHGE, FARM GATE (kg CO2e/kg)","GHGE, processor gate (kg CO2e/kg)"),INDIRECT($AB7))) -> 0.2134 | AE7: =IF($AB7="DIRECT",$S7,DSTDEV('literature entries'!$D:$AI,IF($J7=1,"ACTIVE GHGE, FARM GATE (kg CO2e/kg)","GHGE, processor gate (kg CO2e/kg)"),INDIRECT($AB7))) -> 0.17992035 | AF7: =IF($AB7="DIRECT",$S7,$AE7/$AD7*$R7) -> 0.17992035
A8: 101078000 | B8: Carrot | C8: weight of roots, with or without peel, excluding tops | E8: 14222 | F8: =N8*H8+T8 -> 1.325856 | G8: =R8*H8+U8 -> 0.091616 | H8: 1.12 | I8: FICRCD | J8: 1 | L8: =IF(ISERROR(GETPIVOTDATA(IF($J8=1,"Count of ACTIVE CED, FARM GATE (MJ/kg)","Count of CED, processor gate (MJ/kg)"),'Pivot Table_CED'!$A$3,"SUB TYPE",$B8)),"PROXY",IF(GETPIVOTDATA(IF($J8=1,"Count of ACTIVE CED, FARM GATE (MJ/kg)","Count of CED, processor gate (MJ/kg)"),'Pivot Table_CED'!$A$3,"SUB TYPE",$B8)=0,"PROXY","DB value")) -> DB value | M8: =IF($L8="PROXY",DCOUNT('literature entries'!$D:$AI,IF($J8=1,"ACTIVE CED, FARM GATE (MJ/kg)","CED, processor gate (MJ/kg)"),INDIRECT($K8)),GETPIVOTDATA(IF($J8=1,"Count of ACTIVE CED, FARM GATE (MJ/kg)","Count of CED, processor gate (MJ/kg)"),'Pivot Table_CED'!$A$3,"SUB TYPE",$B8)) -> 5 | N8: =IF($L8="PROXY",DAVERAGE('literature entries'!$D:$AI,IF($J8=1,"ACTIVE CED, FARM GATE (MJ/kg)","CED, processor gate (MJ/kg)"),INDIRECT($K8)),GETPIVOTDATA(IF($J8=1,"Average of ACTIVE CED, FARM GATE (MJ/kg)","Average of CED, processor gate (MJ/kg)"),'Pivot Table_CED'!$A$3,"SUB TYPE",$B8)) -> 1.1838 | O8: =IF($L8="PROXY",DSTDEV('literature entries'!D:AI,IF($J8=1,"ACTIVE CED, FARM GATE (MJ/kg)","CED, processor gate (MJ/kg)"),INDIRECT($K8)),GETPIVOTDATA(IF($J8=1,"StdDev of ACTIVE CED, FARM GATE (MJ/kg)","StdDev of CED, processor gate (MJ/kg)"),'Pivot Table_CED'!$A$3,"SUB TYPE",$B8)) -> 0.63805815 | P8: =IF(ISERROR(GETPIVOTDATA(IF($J8=1,"Count of ACTIVE GHGE, FARM GATE (kg CO2e/kg)","Count of GHGE, processor gate (kg CO2e/kg)"),'Pivot Table_GHG'!$A$3,"SUB TYPE",$B8)),"PROXY",IF(GETPIVOTDATA(IF($J8=1,"Count of ACTIVE GHGE, FARM GATE (kg CO2e/kg)","Count of GHGE, processor gate (kg CO2e/kg)"),'Pivot Table_GHG'!$A$3,"SUB TYPE",$B8)=0,"PROXY","DB value")) -> DB value | Q8: =IF($P8="PROXY",DCOUNT('literature entries'!$D:$AI,IF($J8=1,"ACTIVE GHGE, FARM GATE (kg CO2e/kg)","GHGE, processor gate (kg CO2e/kg)"),INDIRECT($K8)),GETPIVOTDATA(IF($J8=1,"ACTIVE GHGE, FARM GATE (kg CO2e/kg)","Count of GHGE, processor gate (kg CO2e/kg)"),'Pivot Table_GHG'!$A$3,"SUB TYPE",$B8)) -> 5 | R8: =IF($P8="PROXY",DAVERAGE('literature entries'!$D:$AI,IF($J8=1,"ACTIVE GHGE, FARM GATE (kg CO2e/kg)","GHGE, processor gate (kg CO2e/kg)"),INDIRECT($K8)),GETPIVOTDATA(IF($J8=1,"Average of ACTIVE GHGE, FARM GATE (kg CO2e/kg)","Average of GHGE, processor gate (kg CO2e/kg)"),'Pivot Table_GHG'!$A$3,"SUB TYPE",$B8)) -> 0.0818 | S8: =IF($P8="PROXY",DSTDEV('literature entries'!$D:$AI,IF($J8=1,"ACTIVE GHGE, FARM GATE (kg CO2e/kg)","GHGE, processor gate (kg CO2e/kg)"),INDIRECT($K8)),GETPIVOTDATA(IF($J8=1,"StdDev of ACTIVE GHGE, FARM GATE (kg CO2e/kg)","StdDev of GHGE, processor gate (kg CO2e/kg)"),'Pivot Table_GHG'!$A$3,"SUB TYPE",$B8)) -> 0.051982689 | W8: =IF(L8="PROXY",IF(M8>=5,K8,"need group"),IF(M8>=5,"DIRECT","need group")) -> DIRECT | X8: =IF($W8="DIRECT",M8,DCOUNT('literature entries'!$D:$AI,IF($J8=1,"ACTIVE CED, FARM GATE (MJ/kg)","CED, processor gate (MJ/kg)"),INDIRECT($W8))) -> 5 | Y8: =IF($W8="DIRECT","",DAVERAGE('literature entries'!$D:$AI,IF($J8=1,"ACTIVE CED, FARM GATE (MJ/kg)","CED, processor gate (MJ/kg)"),INDIRECT($W8))) | Z8: =IF($W8="DIRECT",$O8,DSTDEV('literature entries'!$D:$AI,IF($J8=1,"ACTIVE CED, FARM GATE (MJ/kg)","CED, processor gate (MJ/kg)"),INDIRECT($W8))) -> 0.63805815 | AA8: =IF($W8="DIRECT",$O8,$Z8/$Y8*$N8) -> 0.63805815 | AB8: =IF(P8="PROXY",IF(Q8>=5,K8,"need group"),IF(Q8>=5,"DIRECT","need group")) -> DIRECT | AC8: =IF($AB8="DIRECT",Q8,DCOUNT('literature entries'!$D:$AI,IF($J8=1,"ACTIVE GHGE, FARM GATE (kg CO2e/kg)","GHGE, processor gate (kg CO2e/kg)"),INDIRECT($AB8))) -> 5 | AD8: =IF($AB8="DIRECT","",DAVERAGE('literature entries'!$D:$AI,IF($J8=1,"ACTIVE GHGE, FARM GATE (kg CO2e/kg)","GHGE, processor gate (kg CO2e/kg)"),INDIRECT($AB8))) | AE8: =IF($AB8="DIRECT",$S8,DSTDEV('literature entries'!$D:$AI,IF($J8=1,"ACTIVE GHGE, FARM GATE (kg CO2e/kg)","GHGE, processor gate (kg CO2e/kg)"),INDIRECT($AB8))) -> 0.051982689 | AF8: =IF($AB8="DIRECT",$S8,$AE8/$AD8*$R8) -> 0.051982689
A9: 101079000 | B9: Carrot, juice | C9: weight of juice at single strength (or standard dilution) | E9: 630 | F9: =N9*H9+T9 -> 6.607856 | G9: =R9*H9+U9 -> 1.0706951 | H9: 1.12 | I9: FICRCD | J9: 1 | K9: carrot | L9: =IF(ISERROR(GETPIVOTDATA(IF($J9=1,"Count of ACTIVE CED, FARM GATE (MJ/kg)","Count of CED, processor gate (MJ/kg)"),'Pivot Table_CED'!$A$3,"SUB TYPE",$B9)),"PROXY",IF(GETPIVOTDATA(IF($J9=1,"Count of ACTIVE CED, FARM GATE (MJ/kg)","Count of CED, processor gate (MJ/kg)"),'Pivot Table_CED'!$A$3,"SUB TYPE",$B9)=0,"PROXY","DB value")) -> PROXY | M9: =IF($L9="PROXY",DCOUNT('literature entries'!$D:$AI,IF($J9=1,"ACTIVE CED, FARM GATE (MJ/kg)","CED, processor gate (MJ/kg)"),INDIRECT($K9)),GETPIVOTDATA(IF($J9=1,"Count of ACTIVE CED, FARM GATE (MJ/kg)","Count of CED, processor gate (MJ/kg)"),'Pivot Table_CED'!$A$3,"SUB TYPE",$B9)) -> 5 | N9: =IF($L9="PROXY",DAVERAGE('literature entries'!$D:$AI,IF($J9=1,"ACTIVE CED, FARM GATE (MJ/kg)","CED, processor gate (MJ/kg)"),INDIRECT($K9)),GETPIVOTDATA(IF($J9=1,"Average of ACTIVE CED, FARM GATE (MJ/kg)","Average of CED, processor gate (MJ/kg)"),'Pivot Table_CED'!$A$3,"SUB TYPE",$B9)) -> 1.1838 | O9: =IF($L9="PROXY",DSTDEV('literature entries'!D:AI,IF($J9=1,"ACTIVE CED, FARM GATE (MJ/kg)","CED, processor gate (MJ/kg)"),INDIRECT($K9)),GETPIVOTDATA(IF($J9=1,"StdDev of ACTIVE CED, FARM GATE (MJ/kg)","StdDev of CED, processor gate (MJ/kg)"),'Pivot Table_CED'!$A$3,"SUB TYPE",$B9)) -> 0.63805815 | P9: =IF(ISERROR(GETPIVOTDATA(IF($J9=1,"Count of ACTIVE GHGE, FARM GATE (kg CO2e/kg)","Count of GHGE, processor gate (kg CO2e/kg)"),'Pivot Table_GHG'!$A$3,"SUB TYPE",$B9)),"PROXY",IF(GETPIVOTDATA(IF($J9=1,"Count of ACTIVE GHGE, FARM GATE (kg CO2e/kg)","Count of GHGE, processor gate (kg CO2e/kg)"),'Pivot Table_GHG'!$A$3,"SUB TYPE",$B9)=0,"PROXY","DB value")) -> PROXY | Q9: =IF($P9="PROXY",DCOUNT('literature entries'!$D:$AI,IF($J9=1,"ACTIVE GHGE, FARM GATE (kg CO2e/kg)","GHGE, processor gate (kg CO2e/kg)"),INDIRECT($K9)),GETPIVOTDATA(IF($J9=1,"ACTIVE GHGE, FARM GATE (kg CO2e/kg)","Count of GHGE, processor gate (kg CO2e/kg)"),'Pivot Table_GHG'!$A$3,"SUB TYPE",$B9)) -> 5 | R9: =IF($P9="PROXY",DAVERAGE('literature entries'!$D:$AI,IF($J9=1,"ACTIVE GHGE, FARM GATE (kg CO2e/kg)","GHGE, processor gate (kg CO2e/kg)"),INDIRECT($K9)),GETPIVOTDATA(IF($J9=1,"Average of ACTIVE GHGE, FARM GATE (kg CO2e/kg)","Average of GHGE, processor gate (kg CO2e/kg)"),'Pivot Table_GHG'!$A$3,"SUB TYPE",$B9)) -> 0.0818 | S9: =IF($P9="PROXY",DSTDEV('literature entries'!$D:$AI,IF($J9=1,"ACTIVE GHGE, FARM GATE (kg CO2e/kg)","GHGE, processor gate (kg CO2e/kg)"),INDIRECT($K9)),GETPIVOTDATA(IF($J9=1,"StdDev of ACTIVE GHGE, FARM GATE (kg CO2e/kg)","StdDev of GHGE, processor gate (kg CO2e/kg)"),'Pivot Table_GHG'!$A$3,"SUB TYPE",$B9)) -> 0.051982689 | T9: 5.282 | U9: 0.97907913 | W9: roots | X9: =IF($W9="DIRECT",M9,DCOUNT('literature entries'!$D:$AI,IF($J9=1,"ACTIVE CED, FARM GATE (MJ/kg)","CED, processor gate (MJ/kg)"),INDIRECT($W9))) -> 14 | Y9: =IF($W9="DIRECT","",DAVERAGE('literature entries'!$D:$AI,IF($J9=1,"ACTIVE CED, FARM GATE (MJ/kg)","CED, processor gate (MJ/kg)"),INDIRECT($W9))) -> 1.4220714 | Z9: =IF($W9="DIRECT",$O9,DSTDEV('literature entries'!$D:$AI,IF($J9=1,"ACTIVE CED, FARM GATE (MJ/kg)","CED, processor gate (MJ/kg)"),INDIRECT($W9))) -> 0.57442044 | AA9: =IF($W9="DIRECT",$O9,$Z9/$Y9*$N9) -> 0.47817494 | AB9: roots | AC9: =IF($AB9="DIRECT",Q9,DCOUNT('literature entries'!$D:$AI,IF($J9=1,"ACTIVE GHGE, FARM GATE (kg CO2e/kg)","GHGE, processor gate (kg CO2e/kg)"),INDIRECT($AB9))) -> 25 | AD9: =IF($AB9="DIRECT","",DAVERAGE('literature entries'!$D:$AI,IF($J9=1,"ACTIVE GHGE, FARM GATE (kg CO2e/kg)","GHGE, processor gate (kg CO2e/kg)"),INDIRECT($AB9))) -> 0.2134 | AE9: =IF($AB9="DIRECT",$S9,DSTDEV('literature entries'!$D:$AI,IF($J9=1,"ACTIVE GHGE, FARM GATE (kg CO2e/kg)","GHGE, processor gate (kg CO2e/kg)"),INDIRECT($AB9))) -> 0.17992035 | AF9: =IF($AB9="DIRECT",$S9,$AE9/$AD9*$R9) -> 0.068966658
A10: 101100000 | B10: Chicory, roots | C10: weight of roots | E10: 75 | F10: =N10*H10+T10 -> 0.1544 | G10: =R10*H10+U10 -> 0.050446 | H10: 1 | I10: None | J10: 1 | L10: =IF(ISERROR(GETPIVOTDATA(IF($J10=1,"Count of ACTIVE CED, FARM GATE (MJ/kg)","Count of CED, processor gate (MJ/kg)"),'Pivot Table_CED'!$A$3,"SUB TYPE",$B10)),"PROXY",IF(GETPIVOTDATA(IF($J10=1,"Count of ACTIVE CED, FARM GATE (MJ/kg)","Count of CED, processor gate (MJ/kg)"),'Pivot Table_CED'!$A$3,"SUB TYPE",$B10)=0,"PROXY","DB value")) -> DB value | M10: =IF($L10="PROXY",DCOUNT('literature entries'!$D:$AI,IF($J10=1,"ACTIVE CED, FARM GATE (MJ/kg)","CED, processor gate (MJ/kg)"),INDIRECT($K10)),GETPIVOTDATA(IF($J10=1,"Count of ACTIVE CED, FARM GATE (MJ/kg)","Count of CED, processor gate (MJ/kg)"),'Pivot Table_CED'!$A$3,"SUB TYPE",$B10)) -> 2 | N10: =IF($L10="PROXY",DAVERAGE('literature entries'!$D:$AI,IF($J10=1,"ACTIVE CED, FARM GATE (MJ/kg)","CED, processor gate (MJ/kg)"),INDIRECT($K10)),GETPIVOTDATA(IF($J10=1,"Average of ACTIVE CED, FARM GATE (MJ/kg)","Average of CED, processor gate (MJ/kg)"),'Pivot Table_CED'!$A$3,"SUB TYPE",$B10)) -> 0.1544 | O10: =IF($L10="PROXY",DSTDEV('literature entries'!D:AI,IF($J10=1,"ACTIVE CED, FARM GATE (MJ/kg)","CED, processor gate (MJ/kg)"),INDIRECT($K10)),GETPIVOTDATA(IF($J10=1,"StdDev of ACTIVE CED, FARM GATE (MJ/kg)","StdDev of CED, processor gate (MJ/kg)"),'Pivot Table_CED'!$A$3,"SUB TYPE",$B10)) -> 0.01357645 | P10: =IF(ISERROR(GETPIVOTDATA(IF($J10=1,"Count of ACTIVE GHGE, FARM GATE (kg CO2e/kg)","Count of GHGE, processor gate (kg CO2e/kg)"),'Pivot Table_GHG'!$A$3,"SUB TYPE",$B10)),"PROXY",IF(GETPIVOTDATA(IF($J10=1,"Count of ACTIVE GHGE, FARM GATE (kg CO2e/kg)","Count of GHGE, processor gate (kg CO2e/kg)"),'Pivot Table_GHG'!$A$3,"SUB TYPE",$B10)=0,"PROXY","DB value")) -> DB value | Q10: =IF($P10="PROXY",DCOUNT('literature entries'!$D:$AI,IF($J10=1,"ACTIVE GHGE, FARM GATE (kg CO2e/kg)","GHGE, processor gate (kg CO2e/kg)"),INDIRECT($K10)),GETPIVOTDATA(IF($J10=1,"ACTIVE GHGE, FARM GATE (kg CO2e/kg)","Count of GHGE, processor gate (kg CO2e/kg)"),'Pivot Table_GHG'!$A$3,"SUB TYPE",$B10)) -> 2 | R10: =IF($P10="PROXY",DAVERAGE('literature entries'!$D:$AI,IF($J10=1,"ACTIVE GHGE, FARM GATE (kg CO2e/kg)","GHGE, processor gate (kg CO2e/kg)"),INDIRECT($K10)),GETPIVOTDATA(IF($J10=1,"Average of ACTIVE GHGE, FARM GATE (kg CO2e/kg)","Average of GHGE, processor gate (kg CO2e/kg)"),'Pivot Table_GHG'!$A$3,"SUB TYPE",$B10)) -> 0.050446 | S10: =IF($P10="PROXY",DSTDEV('literature entries'!$D:$AI,IF($J10=1,"ACTIVE GHGE, FARM GATE (kg CO2e/kg)","GHGE, processor gate (kg CO2e/kg)"),INDIRECT($K10)),GETPIVOTDATA(IF($J10=1,"StdDev of ACTIVE GHGE, FARM GATE (kg CO2e/kg)","StdDev of GHGE, processor gate (kg CO2e/kg)"),'Pivot Table_GHG'!$A$3,"SUB TYPE",$B10)) -> 0.0090240967 | W10: roots | X10: =IF($W10="DIRECT",M10,DCOUNT('literature entries'!$D:$AI,IF($J10=1,"ACTIVE CED, FARM GATE (MJ/kg)","CED, processor gate (MJ/kg)"),INDIRECT($W10))) -> 14 | Y10: =IF($W10="DIRECT","",DAVERAGE('literature entries'!$D:$AI,IF($J10=1,"ACTIVE CED, FARM GATE (MJ/kg)","CED, processor gate (MJ/kg)"),INDIRECT($W10))) -> 1.4220714 | Z10: =IF($W10="DIRECT",$O10,DSTDEV('literature entries'!$D:$AI,IF($J10=1,"ACTIVE CED, FARM GATE (MJ/kg)","CED, processor gate (MJ/kg)"),INDIRECT($W10))) -> 0.57442044 | AA10: =IF($W10="DIRECT",$O10,$Z10/$Y10*$N10) -> 0.062367131 | AB10: roots | AC10: =IF($AB10="DIRECT",Q10,DCOUNT('literature entries'!$D:$AI,IF($J10=1,"ACTIVE GHGE, FARM GATE (kg CO2e/kg)","GHGE, processor gate (kg CO2e/kg)"),INDIRECT($AB10))) -> 25 | AD10: =IF($AB10="DIRECT","",DAVERAGE('literature entries'!$D:$AI,IF($J10=1,"ACTIVE GHGE, FARM GATE (kg CO2e/kg)","GHGE, processor gate (kg CO2e/kg)"),INDIRECT($AB10))) -> 0.2134 | AE10: =IF($AB10="DIRECT",$S10,DSTDEV('literature entries'!$D:$AI,IF($J10=1,"ACTIVE GHGE, FARM GATE (kg CO2e/kg)","GHGE, processor gate (kg CO2e/kg)"),INDIRECT($AB10))) -> 0.17992035 | AF10: =IF($AB10="DIRECT",$S10,$AE10/$AD10*$R10) -> 0.042531688
A11: 101168000 | B11: Ginseng, dried | C11: dry weight of roots | E11: 1 | F11: =N11*H11+T11 -> 0 | G11: =R11*H11+U11 -> 0.87 | H11: 1 | I11: None | J11: 1 | K11: spices | L11: =IF(ISERROR(GETPIVOTDATA(IF($J11=1,"Count of ACTIVE CED, FARM GATE (MJ/kg)","Count of CED, processor gate (MJ/kg)"),'Pivot Table_CED'!$A$3,"SUB TYPE",$B11)),"PROXY",IF(GETPIVOTDATA(IF($J11=1,"Count of ACTIVE CED, FARM GATE (MJ/kg)","Count of CED, processor gate (MJ/kg)"),'Pivot Table_CED'!$A$3,"SUB TYPE",$B11)=0,"PROXY","DB value")) -> PROXY | M11: =IF($L11="PROXY",DCOUNT('literature entries'!$D:$AI,IF($J11=1,"ACTIVE CED, FARM GATE (MJ/kg)","CED, processor gate (MJ/kg)"),INDIRECT($K11)),GETPIVOTDATA(IF($J11=1,"Count of ACTIVE CED, FARM GATE (MJ/kg)","Count of CED, processor gate (MJ/kg)"),'Pivot Table_CED'!$A$3,"SUB TYPE",$B11)) -> 1 | N11: =IF($L11="PROXY",DAVERAGE('literature entries'!$D:$AI,IF($J11=1,"ACTIVE CED, FARM GATE (MJ/kg)","CED, processor gate (MJ/kg)"),INDIRECT($K11)),GETPIVOTDATA(IF($J11=1,"Average of ACTIVE CED, FARM GATE (MJ/kg)","Average of CED, processor gate (MJ/kg)"),'Pivot Table_CED'!$A$3,"SUB TYPE",$B11)) -> 0 | O11: =IF($L11="PROXY",DSTDEV('literature entries'!D:AI,IF($J11=1,"ACTIVE CED, FARM GATE (MJ/kg)","CED, processor gate (MJ/kg)"),INDIRECT($K11)),GETPIVOTDATA(IF($J11=1,"StdDev of ACTIVE CED, FARM GATE (MJ/kg)","StdDev of CED, processor gate (MJ/kg)"),'Pivot Table_CED'!$A$3,"SUB TYPE",$B11)) -> #DIV/0! | P11: =IF(ISERROR(GETPIVOTDATA(IF($J11=1,"Count of ACTIVE GHGE, FARM GATE (kg CO2e/kg)","Count of GHGE, processor gate (kg CO2e/kg)"),'Pivot Table_GHG'!$A$3,"SUB TYPE",$B11)),"PROXY",IF(GETPIVOTDATA(IF($J11=1,"Count of ACTIVE GHGE, FARM GATE (kg CO2e/kg)","Count of GHGE, processor gate (kg CO2e/kg)"),'Pivot Table_GHG'!$A$3,"SUB TYPE",$B11)=0,"PROXY","DB value")) -> PROXY | Q11: =IF($P11="PROXY",DCOUNT('literature entries'!$D:$AI,IF($J11=1,"ACTIVE GHGE, FARM GATE (kg CO2e/kg)","GHGE, processor gate (kg CO2e/kg)"),INDIRECT($K11)),GETPIVOTDATA(IF($J11=1,"ACTIVE GHGE, FARM GATE (kg CO2e/kg)","Count of GHGE, processor gate (kg CO2e/kg)"),'Pivot Table_GHG'!$A$3,"SUB TYPE",$B11)) -> 2 | R11: =IF($P11="PROXY",DAVERAGE('literature entries'!$D:$AI,IF($J11=1,"ACTIVE GHGE, FARM GATE (kg CO2e/kg)","GHGE, processor gate (kg CO2e/kg)"),INDIRECT($K11)),GETPIVOTDATA(IF($J11=1,"Average of ACTIVE GHGE, FARM GATE (kg CO2e/kg)","Average of GHGE, processor gate (kg CO2e/kg)"),'Pivot Table_GHG'!$A$3,"SUB TYPE",$B11)) -> 0.87 | S11: =IF($P11="PROXY",DSTDEV('literature entries'!$D:$AI,IF($J11=1,"ACTIVE GHGE, FARM GATE (kg CO2e/kg)","GHGE, processor gate (kg CO2e/kg)"),INDIRECT($K11)),GETPIVOTDATA(IF($J11=1,"StdDev of ACTIVE GHGE, FARM GATE (kg CO2e/kg)","StdDev of GHGE, processor gate (kg CO2e/kg)"),'Pivot Table_GHG'!$A$3,"SUB TYPE",$B11)) -> 0 | W11: no var | Z11: 0 | AA11: 0 | AB11: no var | AE11: 0 | AF11: 0
A12: 101190000 | B12: Horseradish | C12: weight of root, ground | E12: 364 | F12: =N12*H12+T12 -> 1.4220714 | G12: =R12*H12+U12 -> 0.2134 | H12: 1 | I12: None | J12: 1 | K12: roots | L12: =IF(ISERROR(GETPIVOTDATA(IF($J12=1,"Count of ACTIVE CED, FARM GATE (MJ/kg)","Count of CED, processor gate (MJ/kg)"),'Pivot Table_CED'!$A$3,"SUB TYPE",$B12)),"PROXY",IF(GETPIVOTDATA(IF($J12=1,"Count of ACTIVE CED, FARM GATE (MJ/kg)","Count of CED, processor gate (MJ/kg)"),'Pivot Table_CED'!$A$3,"SUB TYPE",$B12)=0,"PROXY","DB value")) -> PROXY | M12: =IF($L12="PROXY",DCOUNT('literature entries'!$D:$AI,IF($J12=1,"ACTIVE CED, FARM GATE (MJ/kg)","CED, processor gate (MJ/kg)"),INDIRECT($K12)),GETPIVOTDATA(IF($J12=1,"Count of ACTIVE CED, FARM GATE (MJ/kg)","Count of CED, processor gate (MJ/kg)"),'Pivot Table_CED'!$A$3,"SUB TYPE",$B12)) -> 14 | N12: =IF($L12="PROXY",DAVERAGE('literature entries'!$D:$AI,IF($J12=1,"ACTIVE CED, FARM GATE (MJ/kg)","CED, processor gate (MJ/kg)"),INDIRECT($K12)),GETPIVOTDATA(IF($J12=1,"Average of ACTIVE CED, FARM GATE (MJ/kg)","Average of CED, processor gate (MJ/kg)"),'Pivot Table_CED'!$A$3,"SUB TYPE",$B12)) -> 1.4220714 | O12: =IF($L12="PROXY",DSTDEV('literature entries'!D:AI,IF($J12=1,"ACTIVE CED, FARM GATE (MJ/kg)","CED, processor gate (MJ/kg)"),INDIRECT($K12)),GETPIVOTDATA(IF($J12=1,"StdDev of ACTIVE CED, FARM GATE (MJ/kg)","StdDev of CED, processor gate (MJ/kg)"),'Pivot Table_CED'!$A$3,"SUB TYPE",$B12)) -> 0.57442044 | P12: =IF(ISERROR(GETPIVOTDATA(IF($J12=1,"Count of ACTIVE GHGE, FARM GATE (kg CO2e/kg)","Count of GHGE, processor gate (kg CO2e/kg)"),'Pivot Table_GHG'!$A$3,"SUB TYPE",$B12)),"PROXY",IF(GETPIVOTDATA(IF($J12=1,"Count of ACTIVE GHGE, FARM GATE (kg CO2e/kg)","Count of GHGE, processor gate (kg CO2e/kg)"),'Pivot Table_GHG'!$A$3,"SUB TYPE",$B12)=0,"PROXY","DB value")) -> PROXY | Q12: =IF($P12="PROXY",DCOUNT('literature entries'!$D:$AI,IF($J12=1,"ACTIVE GHGE, FARM GATE (kg CO2e/kg)","GHGE, processor gate (kg CO2e/kg)"),INDIRECT($K12)),GETPIVOTDATA(IF($J12=1,"ACTIVE GHGE, FARM GATE (kg CO2e/kg)","Count of GHGE, processor gate (kg CO2e/kg)"),'Pivot Table_GHG'!$A$3,"SUB TYPE",$B12)) -> 25 | R12: =IF($P12="PROXY",DAVERAGE('literature entries'!$D:$AI,IF($J12=1,"ACTIVE GHGE, FARM GATE (kg CO2e/kg)","GHGE, processor gate (kg CO2e/kg)"),INDIRECT($K12)),GETPIVOTDATA(IF($J12=1,"Average of ACTIVE GHGE, FARM GATE (kg CO2e/kg)","Average of GHGE, processor gate (kg CO2e/kg)"),'Pivot Table_GHG'!$A$3,"SUB TYPE",$B12)) -> 0.2134 | S12: =IF($P12="PROXY",DSTDEV('literature entries'!$D:$AI,IF($J12=1,"ACTIVE GHGE, FARM GATE (kg CO2e/kg)","GHGE, processor gate (kg CO2e/kg)"),INDIRECT($K12)),GETPIVOTDATA(IF($J12=1,"StdDev of ACTIVE GHGE, FARM GATE (kg CO2e/kg)","StdDev of GHGE, processor gate (kg CO2e/kg)"),'Pivot Table_GHG'!$A$3,"SUB TYPE",$B12)) -> 0.17992035 | W12: =IF(L12="PROXY",IF(M12>=5,K12,"need group"),IF(M12>=5,"DIRECT","need group")) -> roots | X12: =IF($W12="DIRECT",M12,DCOUNT('literature entries'!$D:$AI,IF($J12=1,"ACTIVE CED, FARM GATE (MJ/kg)","CED, processor gate (MJ/kg)"),INDIRECT($W12))) -> 14 | Y12: =IF($W12="DIRECT","",DAVERAGE('literature entries'!$D:$AI,IF($J12=1,"ACTIVE CED, FARM GATE (MJ/kg)","CED, processor gate (MJ/kg)"),INDIRECT($W12))) -> 1.4220714 | Z12: =IF($W12="DIRECT",$O12,DSTDEV('literature entries'!$D:$AI,IF($J12=1,"ACTIVE CED, FARM GATE (MJ/kg)","CED, processor gate (MJ/kg)"),INDIRECT($W12))) -> 0.57442044 | AA12: =IF($W12="DIRECT",$O12,$Z12/$Y12*$N12) -> 0.57442044 | AB12: =IF(P12="PROXY",IF(Q12>=5,K12,"need group"),IF(Q12>=5,"DIRECT","need group")) -> roots | AC12: =IF($AB12="DIRECT",Q12,DCOUNT('literature entries'!$D:$AI,IF($J12=1,"ACTIVE GHGE, FARM GATE (kg CO2e/kg)","GHGE, processor gate (kg CO2e/kg)"),INDIRECT($AB12))) -> 25 | AD12: =IF($AB12="DIRECT","",DAVERAGE('literature entries'!$D:$AI,IF($J12=1,"ACTIVE GHGE, FARM GATE (kg CO2e/kg)","GHGE, processor gate (kg CO2e/kg)"),INDIRECT($AB12))) -> 0.2134 | AE12: =IF($AB12="DIRECT",$S12,DSTDEV('literature entries'!$D:$AI,IF($J12=1,"ACTIVE GHGE, FARM GATE (kg CO2e/kg)","GHGE, processor gate (kg CO2e/kg)"),INDIRECT($AB12))) -> 0.17992035 | AF12: =IF($AB12="DIRECT",$S12,$AE12/$AD12*$R12) -> 0.17992035
A13: 101251000 | B13: Parsnip | C13: weight of roots with or without peel | E13: 54 | F13: =N13*H13+T13 -> 1.6211614 | G13: =R13*H13+U13 -> 0.243276 | H13: 1.14 | I13: FICRCD | J13: 1 | K13: roots | L13: =IF(ISERROR(GETPIVOTDATA(IF($J13=1,"Count of ACTIVE CED, FARM GATE (MJ/kg)","Count of CED, processor gate (MJ/kg)"),'Pivot Table_CED'!$A$3,"SUB TYPE",$B13)),"PROXY",IF(GETPIVOTDATA(IF($J13=1,"Count of ACTIVE CED, FARM GATE (MJ/kg)","Count of CED, processor gate (MJ/kg)"),'Pivot Table_CED'!$A$3,"SUB TYPE",$B13)=0,"PROXY","DB value")) -> PROXY | M13: =IF($L13="PROXY",DCOUNT('literature entries'!$D:$AI,IF($J13=1,"ACTIVE CED, FARM GATE (MJ/kg)","CED, processor gate (MJ/kg)"),INDIRECT($K13)),GETPIVOTDATA(IF($J13=1,"Count of ACTIVE CED, FARM GATE (MJ/kg)","Count of CED, processor gate (MJ/kg)"),'Pivot Table_CED'!$A$3,"SUB TYPE",$B13)) -> 14 | N13: =IF($L13="PROXY",DAVERAGE('literature entries'!$D:$AI,IF($J13=1,"ACTIVE CED, FARM GATE (MJ/kg)","CED, processor gate (MJ/kg)"),INDIRECT($K13)),GETPIVOTDATA(IF($J13=1,"Average of ACTIVE CED, FARM GATE (MJ/kg)","Average of CED, processor gate (MJ/kg)"),'Pivot Table_CED'!$A$3,"SUB TYPE",$B13)) -> 1.4220714 | O13: =IF($L13="PROXY",DSTDEV('literature entries'!D:AI,IF($J13=1,"ACTIVE CED, FARM GATE (MJ/kg)","CED, processor gate (MJ/kg)"),INDIRECT($K13)),GETPIVOTDATA(IF($J13=1,"StdDev of ACTIVE CED, FARM GATE (MJ/kg)","StdDev of CED, processor gate (MJ/kg)"),'Pivot Table_CED'!$A$3,"SUB TYPE",$B13)) -> 0.57442044 | P13: =IF(ISERROR(GETPIVOTDATA(IF($J13=1,"Count of ACTIVE GHGE, FARM GATE (kg CO2e/kg)","Count of GHGE, processor gate (kg CO2e/kg)"),'Pivot Table_GHG'!$A$3,"SUB TYPE",$B13)),"PROXY",IF(GETPIVOTDATA(IF($J13=1,"Count of ACTIVE GHGE, FARM GATE (kg CO2e/kg)","Count of GHGE, processor gate (kg CO2e/kg)"),'Pivot Table_GHG'!$A$3,"SUB TYPE",$B13)=0,"PROXY","DB value")) -> PROXY | Q13: =IF($P13="PROXY",DCOUNT('literature entries'!$D:$AI,IF($J13=1,"ACTIVE GHGE, FARM GATE (kg CO2e/kg)","GHGE, processor gate (kg CO2e/kg)"),INDIRECT($K13)),GETPIVOTDATA(IF($J13=1,"ACTIVE GHGE, FARM GATE (kg CO2e/kg)","Count of GHGE, processor gate (kg CO2e/kg)"),'Pivot Table_GHG'!$A$3,"SUB TYPE",$B13)) -> 25 | R13: =IF($P13="PROXY",DAVERAGE('literature entries'!$D:$AI,IF($J13=1,"ACTIVE GHGE, FARM GATE (kg CO2e/kg)","GHGE, processor gate (kg CO2e/kg)"),INDIRECT($K13)),GETPIVOTDATA(IF($J13=1,"Average of ACTIVE GHGE, FARM GATE (kg CO2e/kg)","Average of GHGE, processor gate (kg CO2e/kg)"),'Pivot Table_GHG'!$A$3,"SUB TYPE",$B13)) -> 0.2134 | S13: =IF($P13="PROXY",DSTDEV('literature entries'!$D:$AI,IF($J13=1,"ACTIVE GHGE, FARM GATE (kg CO2e/kg)","GHGE, processor gate (kg CO2e/kg)"),INDIRECT($K13)),GETPIVOTDATA(IF($J13=1,"StdDev of ACTIVE GHGE, FARM GATE (kg CO2e/kg)","StdDev of GHGE, processor gate (kg CO2e/kg)"),'Pivot Table_GHG'!$A$3,"SUB TYPE",$B13)) -> 0.17992035 | W13: =IF(L13="PROXY",IF(M13>=5,K13,"need group"),IF(M13>=5,"DIRECT","need group")) -> roots | X13: =IF($W13="DIRECT",M13,DCOUNT('literature entries'!$D:$AI,IF($J13=1,"ACTIVE CED, FARM GATE (MJ/kg)","CED, processor gate (MJ/kg)"),INDIRECT($W13))) -> 14 | Y13: =IF($W13="DIRECT","",DAVERAGE('literature entries'!$D:$AI,IF($J13=1,"ACTIVE CED, FARM GATE (MJ/kg)","CED, processor gate (MJ/kg)"),INDIRECT($W13))) -> 1.4220714 | Z13: =IF($W13="DIRECT",$O13,DSTDEV('literature entries'!$D:$AI,IF($J13=1,"ACTIVE CED, FARM GATE (MJ/kg)","CED, processor gate (MJ/kg)"),INDIRECT($W13))) -> 0.57442044 | AA13: =IF($W13="DIRECT",$O13,$Z13/$Y13*$N13) -> 0.57442044 | AB13: =IF(P13="PROXY",IF(Q13>=5,K13,"need group"),IF(Q13>=5,"DIRECT","need group")) -> roots | AC13: =IF($AB13="DIRECT",Q13,DCOUNT('literature entries'!$D:$AI,IF($J13=1,"ACTIVE GHGE, FARM GATE (kg CO2e/kg)","GHGE, processor gate (kg CO2e/kg)"),INDIRECT($AB13))) -> 25 | AD13: =IF($AB13="DIRECT","",DAVERAGE('literature entries'!$D:$AI,IF($J13=1,"ACTIVE GHGE, FARM GATE (kg CO2e/kg)","GHGE, processor gate (kg CO2e/kg)"),INDIRECT($AB13))) -> 0.2134 | AE13: =IF($AB13="DIRECT",$S13,DSTDEV('literature entries'!$D:$AI,IF($J13=1,"ACTIVE GHGE, FARM GATE (kg CO2e/kg)","GHGE, processor gate (kg CO2e/kg)"),INDIRECT($AB13))) -> 0.17992035 | AF13: =IF($AB13="DIRECT",$S13,$AE13/$AD13*$R13) -> 0.17992035
A14: 101314000 | B14: Radish, roots | C14: weight of roots | E14: 503 | F14: =N14*H14+T14 -> 1.5784993 | G14: =R14*H14+U14 -> 0.236874 | H14: 1.11 | I14: FICRCD | J14: 1 | K14: roots | L14: =IF(ISERROR(GETPIVOTDATA(IF($J14=1,"Count of ACTIVE CED, FARM GATE (MJ/kg)","Count of CED, processor gate (MJ/kg)"),'Pivot Table_CED'!$A$3,"SUB TYPE",$B14)),"PROXY",IF(GETPIVOTDATA(IF($J14=1,"Count of ACTIVE CED, FARM GATE (MJ/kg)","Count of CED, processor gate (MJ/kg)"),'Pivot Table_CED'!$A$3,"SUB TYPE",$B14)=0,"PROXY","DB value")) -> PROXY | M14: =IF($L14="PROXY",DCOUNT('literature entries'!$D:$AI,IF($J14=1,"ACTIVE CED, FARM GATE (MJ/kg)","CED, processor gate (MJ/kg)"),INDIRECT($K14)),GETPIVOTDATA(IF($J14=1,"Count of ACTIVE CED, FARM GATE (MJ/kg)","Count of CED, processor gate (MJ/kg)"),'Pivot Table_CED'!$A$3,"SUB TYPE",$B14)) -> 14 | N14: =IF($L14="PROXY",DAVERAGE('literature entries'!$D:$AI,IF($J14=1,"ACTIVE CED, FARM GATE (MJ/kg)","CED, processor gate (MJ/kg)"),INDIRECT($K14)),GETPIVOTDATA(IF($J14=1,"Average of ACTIVE CED, FARM GATE (MJ/kg)","Average of CED, processor gate (MJ/kg)"),'Pivot Table_CED'!$A$3,"SUB TYPE",$B14)) -> 1.4220714 | O14: =IF($L14="PROXY",DSTDEV('literature entries'!D:AI,IF($J14=1,"ACTIVE CED, FARM GATE (MJ/kg)","CED, processor gate (MJ/kg)"),INDIRECT($K14)),GETPIVOTDATA(IF($J14=1,"StdDev of ACTIVE CED, FARM GATE (MJ/kg)","StdDev of CED, processor gate (MJ/kg)"),'Pivot Table_CED'!$A$3,"SUB TYPE",$B14)) -> 0.57442044 | P14: =IF(ISERROR(GETPIVOTDATA(IF($J14=1,"Count of ACTIVE GHGE, FARM GATE (kg CO2e/kg)","Count of GHGE, processor gate (kg CO2e/kg)"),'Pivot Table_GHG'!$A$3,"SUB TYPE",$B14)),"PROXY",IF(GETPIVOTDATA(IF($J14=1,"Count of ACTIVE GHGE, FARM GATE (kg CO2e/kg)","Count of GHGE, processor gate (kg CO2e/kg)"),'Pivot Table_GHG'!$A$3,"SUB TYPE",$B14)=0,"PROXY","DB value")) -> PROXY | Q14: =IF($P14="PROXY",DCOUNT('literature entries'!$D:$AI,IF($J14=1,"ACTIVE GHGE, FARM GATE (kg CO2e/kg)","GHGE, processor gate (kg CO2e/kg)"),INDIRECT($K14)),GETPIVOTDATA(IF($J14=1,"ACTIVE GHGE, FARM GATE (kg CO2e/kg)","Count of GHGE, processor gate (kg CO2e/kg)"),'Pivot Table_GHG'!$A$3,"SUB TYPE",$B14)) -> 25 | R14: =IF($P14="PROXY",DAVERAGE('literature entries'!$D:$AI,IF($J14=1,"ACTIVE GHGE, FARM GATE (kg CO2e/kg)","GHGE, processor gate (kg CO2e/kg)"),INDIRECT($K14)),GETPIVOTDATA(IF($J14=1,"Average of ACTIVE GHGE, FARM GATE (kg CO2e/kg)","Average of GHGE, processor gate (kg CO2e/kg)"),'Pivot Table_GHG'!$A$3,"SUB TYPE",$B14)) -> 0.2134 | S14: =IF($P14="PROXY",DSTDEV('literature entries'!$D:$AI,IF($J14=1,"ACTIVE GHGE, FARM GATE (kg CO2e/kg)","GHGE, processor gate (kg CO2e/kg)"),INDIRECT($K14)),GETPIVOTDATA(IF($J14=1,"StdDev of ACTIVE GHGE, FARM GATE (kg CO2e/kg)","StdDev of GHGE, processor gate (kg CO2e/kg)"),'Pivot Table_GHG'!$A$3,"SUB TYPE",$B14)) -> 0.17992035 | W14: =IF(L14="PROXY",IF(M14>=5,K14,"need group"),IF(M14>=5,"DIRECT","need group")) -> roots | X14: =IF($W14="DIRECT",M14,DCOUNT('literature entries'!$D:$AI,IF($J14=1,"ACTIVE CED, FARM GATE (MJ/kg)","CED, processor gate (MJ/kg)"),INDIRECT($W14))) -> 14 | Y14: =IF($W14="DIRECT","",DAVERAGE('literature entries'!$D:$AI,IF($J14=1,"ACTIVE CED, FARM GATE (MJ/kg)","CED, processor gate (MJ/kg)"),INDIRECT($W14))) -> 1.4220714 | Z14: =IF($W14="DIRECT",$O14,DSTDEV('literature entries'!$D:$AI,IF($J14=1,"ACTIVE CED, FARM GATE (MJ/kg)","CED, processor gate (MJ/kg)"),INDIRECT($W14))) -> 0.57442044 | AA14: =IF($W14="DIRECT",$O14,$Z14/$Y14*$N14) -> 0.57442044 | AB14: =IF(P14="PROXY",IF(Q14>=5,K14,"need group"),IF(Q14>=5,"DIRECT","need group")) -> roots | AC14: =IF($AB14="DIRECT",Q14,DCOUNT('literature entries'!$D:$AI,IF($J14=1,"ACTIVE GHGE, FARM GATE (kg CO2e/kg)","GHGE, processor gate (kg CO2e/kg)"),INDIRECT($AB14))) -> 25 | AD14: =IF($AB14="DIRECT","",DAVERAGE('literature entries'!$D:$AI,IF($J14=1,"ACTIVE GHGE, FARM GATE (kg CO2e/kg)","GHGE, processor gate (kg CO2e/kg)"),INDIRECT($AB14))) -> 0.2134 | AE14: =IF($AB14="DIRECT",$S14,DSTDEV('literature entries'!$D:$AI,IF($J14=1,"ACTIVE GHGE, FARM GATE (kg CO2e/kg)","GHGE, processor gate (kg CO2e/kg)"),INDIRECT($AB14))) -> 0.17992035 | AF14: =IF($AB14="DIRECT",$S14,$AE14/$AD14*$R14) -> 0.17992035
A15: 101316000 | B15: Radish, Oriental, roots | C15: weight of roots | E15: 7 | F15: =N15*H15+T15 -> 1.8060307 | G15: =R15*H15+U15 -> 0.271018 | H15: 1.27 | I15: FICRCD | J15: 1 | K15: roots | L15: =IF(ISERROR(GETPIVOTDATA(IF($J15=1,"Count of ACTIVE CED, FARM GATE (MJ/kg)","Count of CED, processor gate (MJ/kg)"),'Pivot Table_CED'!$A$3,"SUB TYPE",$B15)),"PROXY",IF(GETPIVOTDATA(IF($J15=1,"Count of ACTIVE CED, FARM GATE (MJ/kg)","Count of CED, processor gate (MJ/kg)"),'Pivot Table_CED'!$A$3,"SUB TYPE",$B15)=0,"PROXY","DB value")) -> PROXY | M15: =IF($L15="PROXY",DCOUNT('literature entries'!$D:$AI,IF($J15=1,"ACTIVE CED, FARM GATE (MJ/kg)","CED, processor gate (MJ/kg)"),INDIRECT($K15)),GETPIVOTDATA(IF($J15=1,"Count of ACTIVE CED, FARM GATE (MJ/kg)","Count of CED, processor gate (MJ/kg)"),'Pivot Table_CED'!$A$3,"SUB TYPE",$B15)) -> 14 | N15: =IF($L15="PROXY",DAVERAGE('literature entries'!$D:$AI,IF($J15=1,"ACTIVE CED, FARM GATE (MJ/kg)","CED, processor gate (MJ/kg)"),INDIRECT($K15)),GETPIVOTDATA(IF($J15=1,"Average of ACTIVE CED, FARM GATE (MJ/kg)","Average of CED, processor gate (MJ/kg)"),'Pivot Table_CED'!$A$3,"SUB TYPE",$B15)) -> 1.4220714 | O15: =IF($L15="PROXY",DSTDEV('literature entries'!D:AI,IF($J15=1,"ACTIVE CED, FARM GATE (MJ/kg)","CED, processor gate (MJ/kg)"),INDIRECT($K15)),GETPIVOTDATA(IF($J15=1,"StdDev of ACTIVE CED, FARM GATE (MJ/kg)","StdDev of CED, processor gate (MJ/kg)"),'Pivot Table_CED'!$A$3,"SUB TYPE",$B15)) -> 0.57442044 | P15: =IF(ISERROR(GETPIVOTDATA(IF($J15=1,"Count of ACTIVE GHGE, FARM GATE (kg CO2e/kg)","Count of GHGE, processor gate (kg CO2e/kg)"),'Pivot Table_GHG'!$A$3,"SUB TYPE",$B15)),"PROXY",IF(GETPIVOTDATA(IF($J15=1,"Count of ACTIVE GHGE, FARM GATE (kg CO2e/kg)","Count of GHGE, processor gate (kg CO2e/kg)"),'Pivot Table_GHG'!$A$3,"SUB TYPE",$B15)=0,"PROXY","DB value")) -> PROXY | Q15: =IF($P15="PROXY",DCOUNT('literature entries'!$D:$AI,IF($J15=1,"ACTIVE GHGE, FARM GATE (kg CO2e/kg)","GHGE, processor gate (kg CO2e/kg)"),INDIRECT($K15)),GETPIVOTDATA(IF($J15=1,"ACTIVE GHGE, FARM GATE (kg CO2e/kg)","Count of GHGE, processor gate (kg CO2e/kg)"),'Pivot Table_GHG'!$A$3,"SUB TYPE",$B15)) -> 25 | R15: =IF($P15="PROXY",DAVERAGE('literature entries'!$D:$AI,IF($J15=1,"ACTIVE GHGE, FARM GATE (kg CO2e/kg)","GHGE, processor gate (kg CO2e/kg)"),INDIRECT($K15)),GETPIVOTDATA(IF($J15=1,"Average of ACTIVE GHGE, FARM GATE (kg CO2e/kg)","Average of GHGE, processor gate (kg CO2e/kg)"),'Pivot Table_GHG'!$A$3,"SUB TYPE",$B15)) -> 0.2134 | S15: =IF($P15="PROXY",DSTDEV('literature entries'!$D:$AI,IF($J15=1,"ACTIVE GHGE, FARM GATE (kg CO2e/kg)","GHGE, processor gate (kg CO2e/kg)"),INDIRECT($K15)),GETPIVOTDATA(IF($J15=1,"StdDev of ACTIVE GHGE, FARM GATE (kg CO2e/kg)","StdDev of GHGE, processor gate (kg CO2e/kg)"),'Pivot Table_GHG'!$A$3,"SUB TYPE",$B15)) -> 0.17992035 | W15: =IF(L15="PROXY",IF(M15>=5,K15,"need group"),IF(M15>=5,"DIRECT","need group")) -> roots | X15: =IF($W15="DIRECT",M15,DCOUNT('literature entries'!$D:$AI,IF($J15=1,"ACTIVE CED, FARM GATE (MJ/kg)","CED, processor gate (MJ/kg)"),INDIRECT($W15))) -> 14 | Y15: =IF($W15="DIRECT","",DAVERAGE('literature entries'!$D:$AI,IF($J15=1,"ACTIVE CED, FARM GATE (MJ/kg)","CED, processor gate (MJ/kg)"),INDIRECT($W15))) -> 1.4220714 | Z15: =IF($W15="DIRECT",$O15,DSTDEV('literature entries'!$D:$AI,IF($J15=1,"ACTIVE CED, FARM GATE (MJ/kg)","CED, processor gate (MJ/kg)"),INDIRECT($W15))) -> 0.57442044 | AA15: =IF($W15="DIRECT",$O15,$Z15/$Y15*$N15) -> 0.57442044 | AB15: =IF(P15="PROXY",IF(Q15>=5,K15,"need group"),IF(Q15>=5,"DIRECT","need group")) -> roots | AC15: =IF($AB15="DIRECT",Q15,DCOUNT('literature entries'!$D:$AI,IF($J15=1,"ACTIVE GHGE, FARM GATE (kg CO2e/kg)","GHGE, processor gate (kg CO2e/kg)"),INDIRECT($AB15))) -> 25 | AD15: =IF($AB15="DIRECT","",DAVERAGE('literature entries'!$D:$AI,IF($J15=1,"ACTIVE GHGE, FARM GATE (kg CO2e/kg)","GHGE, processor gate (kg CO2e/kg)"),INDIRECT($AB15))) -> 0.2134 | AE15: =IF($AB15="DIRECT",$S15,DSTDEV('literature entries'!$D:$AI,IF($J15=1,"ACTIVE GHGE, FARM GATE (kg CO2e/kg)","GHGE, processor gate (kg CO2e/kg)"),INDIRECT($AB15))) -> 0.17992035 | AF15: =IF($AB15="DIRECT",$S15,$AE15/$AD15*$R15) -> 0.17992035
A16: 101327000 | B16: Rutabaga | C16: weight of roots; excluding tops | E16: 265 | F16: =N16*H16+T16 -> 1.6780443 | G16: =R16*H16+U16 -> 0.251812 | H16: 1.18 | I16: FICRCD | J16: 1 | K16: roots | L16: =IF(ISERROR(GETPIVOTDATA(IF($J16=1,"Count of ACTIVE CED, FARM GATE (MJ/kg)","Count of CED, processor gate (MJ/kg)"),'Pivot Table_CED'!$A$3,"SUB TYPE",$B16)),"PROXY",IF(GETPIVOTDATA(IF($J16=1,"Count of ACTIVE CED, FARM GATE (MJ/kg)","Count of CED, processor gate (MJ/kg)"),'Pivot Table_CED'!$A$3,"SUB TYPE",$B16)=0,"PROXY","DB value")) -> PROXY | M16: =IF($L16="PROXY",DCOUNT('literature entries'!$D:$AI,IF($J16=1,"ACTIVE CED, FARM GATE (MJ/kg)","CED, processor gate (MJ/kg)"),INDIRECT($K16)),GETPIVOTDATA(IF($J16=1,"Count of ACTIVE CED, FARM GATE (MJ/kg)","Count of CED, processor gate (MJ/kg)"),'Pivot Table_CED'!$A$3,"SUB TYPE",$B16)) -> 14 | N16: =IF($L16="PROXY",DAVERAGE('literature entries'!$D:$AI,IF($J16=1,"ACTIVE CED, FARM GATE (MJ/kg)","CED, processor gate (MJ/kg)"),INDIRECT($K16)),GETPIVOTDATA(IF($J16=1,"Average of ACTIVE CED, FARM GATE (MJ/kg)","Average of CED, processor gate (MJ/kg)"),'Pivot Table_CED'!$A$3,"SUB TYPE",$B16)) -> 1.4220714 | O16: =IF($L16="PROXY",DSTDEV('literature entries'!D:AI,IF($J16=1,"ACTIVE CED, FARM GATE (MJ/kg)","CED, processor gate (MJ/kg)"),INDIRECT($K16)),GETPIVOTDATA(IF($J16=1,"StdDev of ACTIVE CED, FARM GATE (MJ/kg)","StdDev of CED, processor gate (MJ/kg)"),'Pivot Table_CED'!$A$3,"SUB TYPE",$B16)) -> 0.57442044 | P16: =IF(ISERROR(GETPIVOTDATA(IF($J16=1,"Count of ACTIVE GHGE, FARM GATE (kg CO2e/kg)","Count of GHGE, processor gate (kg CO2e/kg)"),'Pivot Table_GHG'!$A$3,"SUB TYPE",$B16)),"PROXY",IF(GETPIVOTDATA(IF($J16=1,"Count of ACTIVE GHGE, FARM GATE (kg CO2e/kg)","Count of GHGE, processor gate (kg CO2e/kg)"),'Pivot Table_GHG'!$A$3,"SUB TYPE",$B16)=0,"PROXY","DB value")) -> PROXY | Q16: =IF($P16="PROXY",DCOUNT('literature entries'!$D:$AI,IF($J16=1,"ACTIVE GHGE, FARM GATE (kg CO2e/kg)","GHGE, processor gate (kg CO2e/kg)"),INDIRECT($K16)),GETPIVOTDATA(IF($J16=1,"ACTIVE GHGE, FARM GATE (kg CO2e/kg)","Count of GHGE, processor gate (kg CO2e/kg)"),'Pivot Table_GHG'!$A$3,"SUB TYPE",$B16)) -> 25 | R16: =IF($P16="PROXY",DAVERAGE('literature entries'!$D:$AI,IF($J16=1,"ACTIVE GHGE, FARM GATE (kg CO2e/kg)","GHGE, processor gate (kg CO2e/kg)"),INDIRECT($K16)),GETPIVOTDATA(IF($J16=1,"Average of ACTIVE GHGE, FARM GATE (kg CO2e/kg)","Average of GHGE, processor gate (kg CO2e/kg)"),'Pivot Table_GHG'!$A$3,"SUB TYPE",$B16)) -> 0.2134 | S16: =IF($P16="PROXY",DSTDEV('literature entries'!$D:$AI,IF($J16=1,"ACTIVE GHGE, FARM GATE (kg CO2e/kg)","GHGE, processor gate (kg CO2e/kg)"),INDIRECT($K16)),GETPIVOTDATA(IF($J16=1,"StdDev of ACTIVE GHGE, FARM GATE (kg CO2e/kg)","StdDev of GHGE, processor gate (kg CO2e/kg)"),'Pivot Table_GHG'!$A$3,"SUB TYPE",$B16)) -> 0.17992035 | W16: =IF(L16="PROXY",IF(M16>=5,K16,"need group"),IF(M16>=5,"DIRECT","need group")) -> roots | X16: =IF($W16="DIRECT",M16,DCOUNT('literature entries'!$D:$AI,IF($J16=1,"ACTIVE CED, FARM GATE (MJ/kg)","CED, processor gate (MJ/kg)"),INDIRECT($W16))) -> 14 | Y16: =IF($W16="DIRECT","",DAVERAGE('literature entries'!$D:$AI,IF($J16=1,"ACTIVE CED, FARM GATE (MJ/kg)","CED, processor gate (MJ/kg)"),INDIRECT($W16))) -> 1.4220714 | Z16: =IF($W16="DIRECT",$O16,DSTDEV('literature entries'!$D:$AI,IF($J16=1,"ACTIVE CED, FARM GATE (MJ/kg)","CED, processor gate (MJ/kg)"),INDIRECT($W16))) -> 0.57442044 | AA16: =IF($W16="DIRECT",$O16,$Z16/$Y16*$N16) -> 0.57442044 | AB16: =IF(P16="PROXY",IF(Q16>=5,K16,"need group"),IF(Q16>=5,"DIRECT","need group")) -> roots | AC16: =IF($AB16="DIRECT",Q16,DCOUNT('literature entries'!$D:$AI,IF($J16=1,"ACTIVE GHGE, FARM GATE (kg CO2e/kg)","GHGE, processor gate (kg CO2e/kg)"),INDIRECT($AB16))) -> 25 | AD16: =IF($AB16="DIRECT","",DAVERAGE('literature entries'!$D:$AI,IF($J16=1,"ACTIVE GHGE, FARM GATE (kg CO2e/kg)","GHGE, processor gate (kg CO2e/kg)"),INDIRECT($AB16))) -> 0.2134 | AE16: =IF($AB16="DIRECT",$S16,DSTDEV('literature entries'!$D:$AI,IF($J16=1,"ACTIVE GHGE, FARM GATE (kg CO2e/kg)","GHGE, processor gate (kg CO2e/kg)"),INDIRECT($AB16))) -> 0.17992035 | AF16: =IF($AB16="DIRECT",$S16,$AE16/$AD16*$R16) -> 0.17992035
